Workbook

Sheet Recuperado_Hoja1 (2)
A1: AUTOLUX S.A.
A2: Subsistema Stock
F3: Stock Por Artículo
F5: Suc.: Casa Central - Jujuy Stock: <> 0 Kits de Repuestos: No
A6: Locación | B6: Seg.Locación | C6: Línea | D6: Artículo | E6: Descripción | F6: Ind. | G6: Stock | H6: Cto.Rep. | I6: Cto.Ult.Comp. | J6: Pcio.Vta. | K6: Habilitado | L6: Vta.Últ. 6 Sem.
A7: ??????????? | C7: TOYOTA | D7: 14986300 | E7: 215 / 60 R17 96V DUELER H/P SPORT | F7: IJ | G7: 4 | H7: 237574.47 | J7: 395957.45 | K7: Si
A8: ??????????? | C8: TOYOTA | D8: 16962001 | E8: 195/50 R16 84V ECOPIA EP150 | F8: IJ | G8: 8 | H8: 185124.88 | I8: 189753 | J8: 308541.46 | K8: Si
A9: ??????????? | C9: TOYOTA | D9: 371000KE8000 | E9: CARDAN CON RODAM. | F9: IJ | G9: 1 | H9: 1722645 | I9: 998419.56 | J9: 2460921.4 | K9: Si
A10: ??????????? | C10: TOYOTA | D10: 521290A15000 | E10: COVER, FR BUMPER, LWR | F10: IJ | G10: 1 | H10: 295459.84 | I10: 279352.66 | J10: 422085.48 | K10: Si
A11: ??????????? | C11: TOYOTA | D11: 887060D88000 | E11: TUBE SUB-ASSY, LIQUID | F11: IJ | G11: -1 | H11: 318944.02 | J11: 455634.31 | K11: Si
A12: ??????????? | C12: TOYOTA | D12: 900911 | E12: 235/65 R16C AGILIS 3 | F12: IJ | G12: 4 | H12: 300017.53 | I12: 300017.53 | J12: 500029.21 | K12: Si
A13: ??????????? | C13: TOYOTA | D13: 903168 | E13: 265/60 R18 FRV PRIMACY SUV+ | F13: IJ | G13: 8 | H13: 218082.79 | I13: 218082.65 | J13: 363471.31 | K13: Si
A14: ??????????? | C14: TOYOTA | D14: 997246 | E14: 265/60 R18 LTX TRAIL 114 H | F14: IJ | G14: 12 | H14: 217699.17 | I14: 217699.17 | J14: 362831.95 | K14: Si
A15: B-CENTRO | C15: TOYOTA | D15: 76870YY02100 | E15: BARRA | F15: IJ | G15: 6 | H15: 2147820.6 | I15: 1622459.7 | J15: 3068315.1 | K15: Si
A16: B-CENTRO | C16: TOYOTA | D16: PH3B00KA17FF | E16: BARRA NEGRA GR-S IV | F16: IJ | G16: 2 | H16: 380219.05 | I16: 295767.02 | J16: 543170.07 | K16: Si
A17: D-00-00-A01 | C17: TOYOTA | D17: 088238014000 | E17: LIQUIDO FRENO TOYOTA GENUINO TIPO 3 X 1L | F17: IJ | G17: 102 | H17: 24210.893 | I17: 23620.38 | J17: 34586.99 | K17: Si
A18: D-00-00-B01 | C18: TOYOTA | D18: 088860280500 | E18: ACEITE ATF WS ATM 4L | F18: IJ | G18: 10 | H18: 67921.378 | I18: 67921.38 | J18: 97030.54 | K18: Si
A19: D-00-00-B01 | C19: TOYOTA | D19: 088860300500 | E19: CVT FLUID FE 4L | F19: IJ | G19: 4 | H19: 70085.008 | I19: 68375.62 | J19: 100121.44 | K19: Si
A20: D-00-00-C01 | C20: TOYOTA | D20: 088860270500 | E20: ACEITE TYPE IV -4LTS | F20: IJ | G20: 5 | H20: 41811.028 | I20: 45244.47 | J20: 59730.04 | K20: Si
A21: D-01-00-A01 | C21: TOYOTA | D21: 178010C01000 | E21: FILTRO AIRE | F21: IJ | G21: 65 | H21: 48363.42 | I21: 47508.27 | J21: 69090.6 | K21: Si | L21: 47
A22: D-01-01-A01 | C22: TOYOTA | D22: 178013113100 | E22: FILTRO DE AIRE | F22: IJ | G22: 2 | H22: 51882.341 | I22: 48739.85 | J22: 74117.63 | K22: Si
A23: D-01-01-A02 | C23: TOYOTA | D23: 178010B02000 | E23: FILTRO DE AIRE | F23: IJ | G23: 1 | H23: 38517.752 | I23: 101.56 | J23: 55025.36 | K23: Si
A24: D-01-01-A03 | C24: TOYOTA | D24: 178016707000 | E24: FILTRO DE AIRE | F24: IJ | G24: 3 | H24: 53836.594 | I24: 46960.67 | J24: 76909.42 | K24: Si
A25: D-01-01-A04 | C25: TOYOTA | D25: 871396003000 | E25: FILTRO AIRE ACOND. | F25: IJ | G25: 1 | H25: 40055.939 | I25: 38738.73 | J25: 57222.77 | K25: Si
A26: D-01-01-A05 | C26: TOYOTA | D26: 178017705000 | E26: FILTRO DE AIRE | F26: IJ | G26: 13 | H26: 40228.041 | I26: 39516.73 | J26: 57468.63 | K26: Si
A27: D-01-01-B02 | C27: TOYOTA | D27: 178010Y02000 | E27: FILTRO AIRE | F27: IJ | G27: 31 | H27: 27769.343 | I27: 26905.71 | J27: 39670.49 | K27: Si | L27: 4
A28: D-01-01-C01 | C28: TOYOTA | D28: 178015408000 | E28: FILTRO DE AIRE | F28: IJ | G28: 1 | H28: 53836.594 | I28: 52853.71 | J28: 76909.42 | K28: Si
A29: D-01-01-C02 | C29: TOYOTA | D29: 178013117000 | E29: FILTRO DE AIRE | F29: IJ | G29: 3 | H29: 45200.043 | I29: 24837.31 | J29: 64571.49 | K29: Si
A30: D-01-01-C04 | C30: TOYOTA | D30: 178012702000 | E30: FILTRO DE AIRE | F30: IJ | G30: 2 | H30: 38517.752 | I30: 563.01 | J30: 55025.36 | K30: Si
A31: D-01-01-C06 | C31: TOYOTA | D31: 178017406000 | E31: FILTRO DE AIRE | F31: IJ | G31: 1 | H31: 44790.284 | I31: 42077.35 | J31: 63986.12 | K31: Si
A32: D-01-01-C07 | C32: TOYOTA | D32: 178013702100 | E32: FILTRO DE AIRE | F32: IJ | G32: 1 | H32: 38328.633 | I32: 30803.45 | J32: 54755.19 | K32: Si
A33: D-01-01-D01 | C33: TOYOTA | D33: 178015102000 | E33: FILTRO DE AIRE | F33: IJ | G33: 4 | H33: 52102.981 | I33: 51181.71 | J33: 74432.83 | K33: Si
A34: D-01-01-D02 | C34: TOYOTA | D34: 17801AZA0800 | E34: FILTRO DE AIRE | F34: IJ | G34: 2 | H34: 35271.166 | I34: 33827.7 | J34: 50387.38 | K34: Si
A35: D-01-01-D03 | C35: TOYOTA | D35: 178017006000 | E35: FILTRO DE AIRE | F35: IJ | G35: 1 | H35: 52292.1 | I35: 41177.63 | J35: 74703 | K35: Si
A36: D-01-01-D04 | C36: TOYOTA | D36: 871393004000 | E36: FILTRO AIRE ACOND. | F36: IJ | G36: 3 | H36: 33190.829 | I36: 31781.43 | J36: 47415.47 | K36: Si
A37: D-01-01-E01 | C37: TOYOTA | D37: 178013116000 | E37: ELEMENT SUB-ASSY, AIR CLEANER FILTER | F37: IJ | G37: 8 | H37: 52292.1 | I37: 51367.49 | J37: 74703 | K37: Si
A38: D-01-01-E03 | C38: TOYOTA | D38: 178012801000 | E38: FILTRO DE AIRE | F38: IJ | G38: 1 | H38: 44790.284 | I38: 1631.13 | J38: 63986.12 | K38: Si
A39: D-01-01-E04 | C39: TOYOTA | D39: 178012106000 | E39: FILTRO DE AIRE | F39: IJ | G39: 7 | H39: 27436.493 | I39: 26951.36 | J39: 39194.99 | K39: Si
... A56: D-01-03-B01 | C56: TOYOTA | D56: 90915YZZM300 | E56: FILTRO ACEITE | F56: IJ | G56: 44 | H56: 11881.247 | I56: 11671.16 | J56: 16973.21 | K56: Si
A57: D-01-03-B02 | C57: TOYOTA | D57: 90915TA00500 | E57: FILTRO DE ACEITE | F57: IJ | G57: 50 | H57: 10365.754 | I57: 10182.46 | J57: 14808.22 | K57: Si | L57: 4
...

Sheet 1,Tranf.Pend. Recep
A1: AUTOLUX S.A.
A2: Subsistema Stock
F3: Transferencias de Stock Pendientes de Recepción
F5: Estado: Pendientes Suc.Origen: Todas Suc.Destino: Casa Central - Jujuy Kits de Repuestos: No Observaciones: No Valorizado: Costo de Compra Formato: Detallado
A6: Fecha | C6: Nro. Cpbte. | D6: Sucursal Origen | E6: Sucursal Destino | G6: Usuario | I6: Cantid. Total | K6: CUMPLIMIENTO | L6: Obs
A7: 46055 | C7: 00000999 | D7: Suc. Las Lajitas | E7: Casa Central - Jujuy | G7: Castillo, Jose | I7: =SUBTOTAL(9,I9:I9) -> 0 | J7: 9493.35 | K7: SC | L7: Antigüedad de 1 dia corrido de la tranferencia en analisis - Sin Obs
C8: Linea | D8: Artículo | E8: Ind. | F8: Denominación | I8: Cantid. | K8: Valoriz.
B9: 1 | C9: 815610K26100 | D9: IJ | E9: ACRILICO FARO TRASERO LH | I9: 1 | J9: 9493.35
A10: 46055 | C10: 00002861 | D10: Suc. Tartagal | E10: Casa Central - Jujuy | G10: Zurita, Roberto | I10: =SUBTOTAL(9,I12:I12) -> 0 | J10: 563.01 | K10: SC | L10: Antigüedad de 1 dia corrido de la tranferencia en analisis - Sin Obs
C11: Linea | D11: Artículo | E11: Ind. | F11: Denominación | I11: Cantid. | K11: Valoriz.
B12: 1 | C12: 178012702000 | D12: IJ | E12: FILTRO DE AIRE | I12: 1 | J12: 563.01
F13: Totales Generales | H13: =SUBTOTAL(9,I7:I12) -> 0 | I13: 10056.36
J14: Fecha y Hora de Emisión: 03/02/2026 10:38 Página: 1/1
K15: 1

Sheet 2.Pend.Creditoo
A1: AUTOLUX S.A.
A2: Subsistema Compras
H3: Pendiente Nota Crédito
H4: Suc.: Casa Central - Jujuy Tipo Ped.: Todos Ordenado: Artículo
M5: Cantid. | O5: Cto.Comp. | Q5: =+COUNTIF(Q17:Q39,"sc")/(COUNTIF(Q17:Q39,"sc")+COUNTIF(Q17:Q39,"nc")) -> 0.8
A6: Artículo | B6: Descripción | F6: Fecha | G6: Cuenta | H6: Tipo | I6: Comprobante | J6: Suc. | K6: Cantid. | L6: Tipo Pedido | M6: N° de Remito | N6: Total | O6: Total | P6: Obs | Q6: Cumplimiento
A7: 52119YP90100 | B7: IJ | C7: PARAGOLPE DEL (con faros antinieblas) | F7: 45027 | G7: 1 | H7: Factura | I7: A-0300-00111430 | J7: 2 | K7: 1 | L7: Normal | M7: R-0033-00793070 | N7: 1 | O7: 418480.31
A8: 961364250100 | B8: IJ | C8: CLIP MANGUERA | F8: 45040 | G8: 1 | H8: Factura | I8: A-0300-00112073 | J8: 2 | K8: 1 | L8: Normal | M8: R-0033-00793905 | N8: 1 | O8: 5008.84
A9: 135683901600 | B9: IJ | C9: CORREA DISTRIBUCION | F9: 45069 | G9: 1 | H9: Factura | I9: A-0300-00116267 | J9: 2 | K9: 4 | L9: Normal | M9: R-0033-00798925 | N9: 4 | O9: 448367.88
A10: 043627114000 | B10: IJ | C10: JGO. JUNTAS CAJA TRANSFER | F10: 45231 | G10: 1 | H10: Factura | I10: A-0300-00134535 | J10: 2 | K10: 1 | L10: Normal | N10: 1 | O10: 24621.76
A11: PZ0680000300 | B11: IJ | C11: 12V AIR COMPRESOR (DIGIT - CAT 3 | F11: 45327 | G11: 1 | H11: Factura | I11: A-0300-00144566 | J11: 2 | K11: 1 | L11: Normal | M11: R-0033-00833757 | N11: 1 | O11: 107430.47
A12: 088860280500 | B12: IJ | C12: ACEITE ATF WS ATM 4L | F12: 45581 | G12: 1 | H12: Factura | I12: A-0300-00176708 | J12: 2 | K12: 2 | L12: Normal | N12: 2 | O12: 135842.76
A13: PZ0680000300 | B13: IJ | C13: 12V AIR COMPRESOR (DIGIT - CAT 3 | F13: 45601 | G13: 1 | H13: Factura | I13: A-0300-00178635 | J13: 2 | K13: 1 | L13: Normal | M13: R-0033-00870179 | N13: 2 | O13: 107430.47
A14: 167110L08000 | B14: IJ | C14: DEFLECTOR RADIADOR | F14: 40998 | G14: 1 | H14: Factura | I14: A-0075-00010632 | J14: 2 | K14: 1 | L14: Normal | M14: R-0033-00383043 | N14: 1 | O14: 101455.99
A15: 138011101200 | B15: IJ | C15: BALANCIN VALVULA | F15: 45618 | G15: 1 | H15: Factura | I15: A-0300-00180976 | J15: 2 | K15: 2 | L15: Normal | M15: R-0033-00873034 | N15: 2 | O15: 132295.64
A16: 424310K12000 | B16: IJ | C16: CAMPANA DE FRENO TRAS. | F16: 44684 | G16: 1 | H16: Factura | I16: A-0300-00076403 | J16: 2 | K16: 1 | L16: Normal | M16: R-0033-00750708 | N16: 1 | O16: 247070.57
A17: 08021LL02000 | B17: IJ | C17: LIQ. LIMPIAPARABRISA | F17: 45688 | G17: 10001 | H17: Factura | I17: A-0300-00148818 | J17: 2 | K17: 12 | L17: Normal | N17: 12 | O17: 37490.04
A18: 426110KR8000 | B18: IJ | C18: LLANTA CHAPA 17X6 | F18: 44819 | G18: 1 | H18: Factura | I18: A-0300-00090003 | J18: 2 | K18: 1 | L18: Normal | M18: R-0033-00767489 | N18: 1 | O18: 195101.88
A19: 454903936500 | B19: IJ | C19: BRAZO AUXILIAR | F19: 37956 | G19: 1 | H19: Factura | I19: A-0023-00022679 | J19: 2 | K19: 1 | L19: Normal | M19: R-0009-00086267 | N19: 1 | O19: 25371.15
A20: 480680K05000 | B20: IJ | C20: PARRILA SUSPENSION RH | F20: 44637 | G20: 1 | H20: Factura | I20: A-0300-00071099 | J20: 2 | K20: 1 | L20: Normal | M20: R-0033-00744074 | N20: 1 | O20: 296702.28
A21: 482023588100 | B21: IJ | C21: HOJA ELASTICO | F21: 37925 | G21: 1 | H21: Factura | I21: A-0023-00021389 | J21: 2 | K21: 1 | L21: Normal | M21: R-0009-00082909 | N21: 1 | O21: 87.73
A22: 482100K72000 | B22: IJ | C22: PAQUETE ELASTICOS | F22: 44585 | G22: 1 | H22: Factura | I22: A-0300-00066353 | J22: 2 | K22: 2 | L22: Normal | M22: R-0033-00738141 | N22: 2 | O22: 911030.12
A23: 485314927500 | B23: IJ | C23: AMORTIG.TRASERO | F23: 38895 | G23: 1 | H23: Factura | I23: A-0023-00066548 | J23: 2 | K23: 2 | L23: Normal | M23: R-0009-00225515 | N23: 2 | O23: 224.3
A24: 088238014000 | B24: IJ | C24: LIQUIDO FRENO TOYOTA GENUINO TIPO 3 X 1L | F24: 45688 | G24: 10001 | H24: Factura | I24: A-0300-00148818 | J24: 2 | K24: 10 | L24: Normal | N24: 10 | O24: 236203.8
A25: 521638910100 | B25: IJ | C25: PLACA PARAGOLPE | F25: 37817 | G25: 1 | H25: Factura | I25: A-0023-00016848 | J25: 2 | K25: 1 | L25: Normal | M25: R-0009-00071822 | N25: 1 | O25: 80.59
A26: 753793508000 | B26: IJ | C26: FRANJA LATERAL | F26: 37741 | G26: 1 | H26: Factura | I26: A-0023-00013708 | J26: 2 | K26: 1 | L26: Normal | M26: R-0009-00064270 | N26: 1 | O26: 40.47
A27: 75998AR01000 | B27: IJ | C27: AUTOADHESIVO 4X4 | F27: 44240 | G27: 1 | H27: Factura | I27: A-0300-00034676 | J27: 2 | K27: 2 | L27: Normal | M27: R-0033-00698059 | N27: 2 | O27: 2202.38
A28: 178010L04000 | B28: IJ | C28: FILTRO DE AIRE | F28: 45688 | G28: 10001 | H28: Factura | I28: A-0300-00148818 | J28: 2 | K28: 10 | L28: Normal | N28: 10 | O28: 392026.7
A29: 901190613700 | B29: IJ | C29: BULON | F29: 41333 | G29: 1 | H29: Factura | I29: A-0075-00032789 | J29: 2 | K29: 1 | L29: Normal | M29: R-0033-00416707 | N29: 1 | O29: 2.99
A30: 902012300300 | B30: IJ | C30: ASIENTO RESORTE VALV | F30: 37705 | G30: 1 | H30: Factura | I30: A-0023-00012348 | J30: 2 | K30: 5 | L30: Normal | M30: R-0009-00060688 | N30: 5 | O30: 10.8
A31: 909170604100 | B31: IJ | C31: JUNTA ESCAPE | F31: 37705 | G31: 1 | H31: Factura | I31: A-0023-00012348 | J31: 2 | K31: 1 | L31: Normal | M31: R-0009-00060687 | N31: 1 | O31: 30.75
A32: PH3B00KA1000 | B32: IJ | C32: BARRA DE TRABAJO DC- CAT 1 | F32: 45688 | G32: 10001 | H32: Factura | I32: A-0300-00148818 | J32: 2 | K32: 2 | L32: Normal | N32: 2 | O32: 721097.56
A33: 9913212050AR | B33: IJ | C33: LAMPARA | F33: 41333 | G33: 1 | H33: Factura | I33: A-0075-00032879 | J33: 2 | K33: 10 | L33: Normal | M33: R-0933-00416862 | N33: 10 | O33: 3506.5
A34: PH3B10KA1100 | B34: IJ | C34: LONA CAJA HX 2016 - CAT 2 | F34: 45688 | G34: 10001 | H34: Factura | I34: A-0300-00148818 | J34: 2 | K34: 1 | L34: Normal | N34: 1 | O34: 167954.58
A35: PH7000KM10DO | B35: IJ | C35: JGO ESTRIBO - CAT 2 | F35: 45688 | G35: 10001 | H35: Factura | I35: A-0300-00148818 | J35: 2 | K35: 1 | L35: Normal | N35: 1 | O35: 239039.89 | Q35: NC
A36: BUTERMOACERO | B36: IJ | C36: TERMO DE ACERO INOX. 1LTS | F36: 45733 | G36: 1 | H36: Factura | I36: A-0300-00193274 | J36: 2 | K36: 2 | L36: Normal | M36: R-0033-00888151 | N36: 2 | O36: 130619.84 | P36: Tasa no aprobo el reclamo de los termos, en conocimento luis. | Q36: SC
A37: 136160E01100 | B37: IJ | C37: ENGRANAJE BBA. ACEITE | F37: 45771 | G37: 1 | H37: Factura | I37: A-0200-00197260 | J37: 2 | K37: 1 | L37: Normal | M37: R-0033-00893210 | N37: 1 | O37: 44419.13 | P37: Pendiente de credito reclamado-Aprobado | Q37: SC
A38: 897455002000 | B38: IJ | C38: BATERIA LLAVE TRANSMISORA CR2032 | F38: 45803 | G38: 1 | H38: Factura | I38: A-0300-00200870 | J38: 2 | K38: 1 | L38: Normal | M38: R-0033-00897568 | N38: 1 | O38: 11089.51 | P38: Pendiente de credito reclamado-Aprobado | Q38: SC
A39: 424310K12000 | B39: IJ | C39: CAMPANA DE FRENO TRAS. | F39: 45814 | G39: 1 | H39: Factura | I39: A-0300-00202404 | J39: 2 | K39: 1 | L39: Normal | M39: R-0033-00899488 | N39: 2 | O39: 247070.57 | P39: Pendiente de credito reclamado-Aprobado | Q39: SC
A40: PZU100601500 | B40: IJ | C40: CUBREALFOMFRA STD SC | F40: 40998 | G40: 1 | H40: Factura | I40: A-0075-00010632 | J40: 2 | K40: 1 | L40: Normal | M40: R-0033-00383043 | N40: 1 | O40: 120.28
...

Sheet 3.Remito Pend Carga
A1: Autolux S.A. - Sucursal Salta
A2: Control Integral de Depósito
A3: Fecha:
A4: Remitos pendientes de carga
G5: 1
A6: Fecha Rec. | B6: Nro. Remito | C6: Fecha Carga Siac. | D6: Fecha Ctrol. | E6: Demora (días) | F6: Observacion | G6: Rdo.
A7: 46050 | B7: R-33-932891 | C7: 46050 | D7: 46056 | E7: =+C7-A7 -> 0 | G7: SC
A8: 46055 | B8: R-33-933524 | C8: 46055 | D8: =+D7 -> 46056 | E8: =+C8-A8 -> 0 | G8: SC
A9: 46051 | B9: R-33-933136 | C9: 46051 | D9: =+D8 -> 46056 | E9: =+C9-A9 -> 0 | G9: SC
A10: 46051 | B10: R-33-933109 | C10: 46051 | D10: =+D9 -> 46056 | E10: =+C10-A10 -> 0 | G10: SC
A12: Esta pendiente de implementar la fecha de recepción en sello.

Sheet 4.Inv Rota
A1: AUTOLUX S.A.
A2: Subsistema Stock
F3: Stock Por Artículo
F5: Suc.: Casa Central - Jujuy Stock: <> 0 Kits de Repuestos: No | K5: 1 | L5: =+COUNTIF(L7:L57,"sc")/(COUNTIF(L7:L57,"sc")+COUNTIF(L7:L57,"nc")) -> 0.94117647
A6: Locación | B6: Seg.Locación | C6: Línea | D6: Artículo | E6: Descripción | F6: Ind. | G6: Stock | H6: Conteo | I6: Dif | J6: Obs | K6: Estado Art | L6: Locacion | M6: Cto.Rep. | N6: Stock Valorizado | O6: Cto.Ult.Comp. | P6: Pcio.Vta. | Q6: Habilitado | R6: Vta.Últ. 6 Sem.
A7: D-01-01-C01 | C7: TOYOTA | D7: 178015408000 | E7: FILTRO DE AIRE | F7: IJ | G7: 1 | H7: 1 | I7: =+H7-G7 -> 0 | K7: SC | L7: SC | M7: 53836.594 | N7: =+M7*G7 -> 53836.594 | O7: 52853.71 | P7: 76909.42 | Q7: Si
A8: D-01-01-C02 | C8: TOYOTA | D8: 178013117000 | E8: FILTRO DE AIRE | F8: IJ | G8: 3 | H8: 3 | I8: =+H8-G8 -> 0 | K8: SC | L8: SC | M8: 45200.043 | N8: =+M8*G8 -> 135600.13 | O8: 24837.31 | P8: 64571.49 | Q8: Si
A9: D-01-01-C04 | C9: TOYOTA | D9: 178012702000 | E9: FILTRO DE AIRE | F9: IJ | G9: 2 | H9: 2 | I9: =+H9-G9 -> 0 | K9: SC | L9: SC | M9: 38517.752 | N9: =+M9*G9 -> 77035.504 | O9: 563.01 | P9: 55025.36 | Q9: Si
A10: D-01-01-C06 | C10: TOYOTA | D10: 178017406000 | E10: FILTRO DE AIRE | F10: IJ | G10: 1 | H10: 1 | I10: =+H10-G10 -> 0 | K10: SC | L10: SC | M10: 44790.284 | N10: =+M10*G10 -> 44790.284 | O10: 42077.35 | P10: 63986.12 | Q10: Si
A11: D-01-01-C07 | C11: TOYOTA | D11: 178013702100 | E11: FILTRO DE AIRE | F11: IJ | G11: 1 | H11: 1 | I11: =+H11-G11 -> 0 | K11: SC | L11: SC | M11: 38328.633 | N11: =+M11*G11 -> 38328.633 | O11: 30803.45 | P11: 54755.19 | Q11: Si
A12: D-01-01-D01 | C12: TOYOTA | D12: 178015102000 | E12: FILTRO DE AIRE | F12: IJ | G12: 4 | H12: 4 | I12: =+H12-G12 -> 0 | K12: SC | L12: SC | M12: 52102.981 | N12: =+M12*G12 -> 208411.92 | O12: 51181.71 | P12: 74432.83 | Q12: Si
A13: D-01-01-D02 | C13: TOYOTA | D13: 17801AZA0800 | E13: FILTRO DE AIRE | F13: IJ | G13: 2 | H13: 2 | I13: =+H13-G13 -> 0 | K13: SC | L13: SC | M13: 35271.166 | N13: =+M13*G13 -> 70542.332 | O13: 33827.7 | P13: 50387.38 | Q13: Si
A14: D-01-01-D03 | C14: TOYOTA | D14: 178017006000 | E14: FILTRO DE AIRE | F14: IJ | G14: 1 | H14: 1 | I14: =+H14-G14 -> 0 | K14: SC | L14: SC | M14: 52292.1 | N14: =+M14*G14 -> 52292.1 | O14: 41177.63 | P14: 74703 | Q14: Si
A15: D-01-01-D04 | C15: TOYOTA | D15: 871393004000 | E15: FILTRO AIRE ACOND. | F15: IJ | G15: 3 | H15: 3 | I15: =+H15-G15 -> 0 | K15: SC | L15: SC | M15: 33190.829 | N15: =+M15*G15 -> 99572.487 | O15: 31781.43 | P15: 47415.47 | Q15: Si
A16: D-01-01-E01 | C16: TOYOTA | D16: 178013116000 | E16: ELEMENT SUB-ASSY, AIR CLEANER FILTER | F16: IJ | G16: 8 | H16: 8 | I16: =+H16-G16 -> 0 | J16: Mal Locado | K16: SC | L16: NC | M16: 52292.1 | N16: =+M16*G16 -> 418336.8 | O16: 51367.49 | P16: 74703 | Q16: Si
A17: D-01-01-E03 | C17: TOYOTA | D17: 178012801000 | E17: FILTRO DE AIRE | F17: IJ | G17: 1 | H17: 1 | I17: =+H17-G17 -> 0 | K17: SC | L17: SC | M17: 44790.284 | N17: =+M17*G17 -> 44790.284 | O17: 1631.13 | P17: 63986.12 | Q17: Si
A18: D-01-01-E04 | C18: TOYOTA | D18: 178012106000 | E18: FILTRO DE AIRE | F18: IJ | G18: 7 | H18: 7 | I18: =+H18-G18 -> 0 | K18: SC | L18: SC | M18: 27436.493 | N18: =+M18*G18 -> 192055.45 | O18: 26951.36 | P18: 39194.99 | Q18: Si
A19: D-01-02-A02 | C19: TOYOTA | D19: 885683702000 | E19: FILTRO ANTIPOLEN | F19: IJ | G19: 2 | H19: 2 | I19: =+H19-G19 -> 0 | K19: SC | L19: SC | M19: 33285.392 | N19: =+M19*G19 -> 66570.784 | O19: 1848.74 | P19: 47550.56 | Q19: Si
A20: D-01-02-A04 | C20: TOYOTA | D20: 888802011000 | E20: FILTRO POLEA A/A | F20: IJ | G20: 1 | H20: 1 | I20: =+H20-G20 -> 0 | K20: SC | L20: SC | M20: 1474.123 | N20: =+M20*G20 -> 1474.123 | O20: 141.07 | P20: 2105.89 | Q20: Si
A21: D-01-02-A05 | C21: TOYOTA | D21: 871393010000 | E21: FILTRO ANTIPOLEN | F21: IJ | G21: 1 | H21: 1 | I21: =+H21-G21 -> 0 | K21: SC | L21: SC | M21: 68485.634 | N21: =+M21*G21 -> 68485.634 | O21: 42675.27 | P21: 97836.62 | Q21: Si
A22: D-01-02-A06 | C22: TOYOTA | D22: 871392802000 | E22: FILTRO AIRE ACOND. | F22: IJ | G22: 4 | H22: 4 | I22: =+H22-G22 -> 0 | K22: SC | L22: SC | M22: 33285.392 | N22: =+M22*G22 -> 133141.57 | O22: 32673.62 | P22: 47550.56 | Q22: Si
A23: D-01-02-A08 | C23: TOYOTA | D23: 871390K04000 | E23: FILTRO AIRE ACOND. | F23: IJ | G23: 1 | H23: 1 | I23: =+H23-G23 -> 0 | K23: SC | L23: SC | M23: 21890.82 | N23: =+M23*G23 -> 21890.82 | O23: 20953.54 | P23: 31272.6 | Q23: Si
A24: D-01-04-B01 | C24: TOYOTA | D24: 41523701000 | E24: CONJ.FILTRO ACEITE | F24: IJ | G24: 25 | H24: 25 | I24: =+H24-G24 -> 0 | J24: Poseia un faltante de -1. Se encontraba 1 art separado, facturado a-48-33367 - Sin obs. | K24: SC | L24: SC | M24: 17820.383 | N24: =+M24*G24 -> 445509.58 | O24: 17505.27 | P24: 25457.69 | Q24: Si | R24: 9
A25: D-01-04-B02 | C25: TOYOTA | D25: 770241240000 | E25: PLATO BBA. COMB. | F25: IJ | G25: 4 | H25: 4 | I25: =+H25-G25 -> 0 | K25: SC | L25: SC | M25: 74895.527 | N25: =+M25*G25 -> 299582.11 | O25: 70685.14 | P25: 106993.61 | Q25: Si
A26: D-01-04-C01 | C26: TOYOTA | D26: 770241003000 | E26: PLACA SUCCION COMB. | F26: IJ | G26: 1 | H26: 1 | I26: =+H26-G26 -> 0 | K26: SC | L26: SC | M26: 111168.85 | N26: =+M26*G26 -> 111168.85 | O26: 5723.25 | P26: 158812.64 | Q26: Si
A27: D-01-04-C02 | C27: TOYOTA | D27: 770241218000 | E27: PLATO BBA. COMB. | F27: IJ | G27: 2 | H27: 2 | I27: =+H27-G27 -> 0 | K27: SC | L27: SC | M27: 124881.96 | N27: =+M27*G27 -> 249763.92 | O27: 122623 | P27: 178402.8 | Q27: Si | R27: 1
A28: D-01-04-C03 | C28: TOYOTA | D28: 770244211000 | E28: PLATO BBA. COMBUSTIBLE | F28: IJ | G28: 1 | H28: 1 | I28: =+H28-G28 -> 0 | K28: SC | L28: SC | M28: 125922.74 | N28: =+M28*G28 -> 125922.74 | O28: 109859.02 | P28: 179889.63 | Q28: Si
A29: D-01-04-C04 | C29: TOYOTA | D29: 770241224000 | E29: PLATO BOMBA COMB. | F29: IJ | G29: 4 | H29: 4 | I29: =+H29-G29 -> 0 | K29: SC | L29: SC | M29: 171821.26 | N29: =+M29*G29 -> 687285.03 | O29: 16630.28 | P29: 245458.94 | Q29: Si
A30: D-01-04-D01 | C30: TOYOTA | D30: 233900E01100 | E30: FILTRO DE COMBUSTIBLE | F30: IJ | G30: 10 | H30: 10 | I30: =+H30-G30 -> 0 | K30: SC | L30: SC | M30: 138153.27 | N30: =+M30*G30 -> 1381532.7 | O30: 133674.4 | P30: 197361.82 | Q30: Si
A31: D-01-04-D02 | C31: TOYOTA | D31: 909153000300 | E31: FILTRO ACEITE | F31: IJ | G31: 3 | H31: 3 | I31: =+H31-G31 -> 0 | K31: SC | L31: SC | M31: 45614.849 | N31: =+M31*G31 -> 136844.55 | O31: 42879.22 | P31: 65164.07 | Q31: Si
A32: D-01-05-G04 | C32: TOYOTA | D32: 156013302100 | E32: FILTRO ACEITE | F32: IJ | G32: 1 | H32: 1 | I32: =+H32-G32 -> 0 | K32: SC | L32: SC | M32: 16094.239 | N32: =+M32*G32 -> 16094.239 | P32: 22991.77 | Q32: Si
A33: D-01-05-G06 | C33: TOYOTA | D33: 909152000400 | E33: FILTRO ACEITE | F33: IJ | G33: 1 | H33: 1 | I33: =+H33-G33 -> 0 | K33: SC | L33: SC | M33: 22473.941 | N33: =+M33*G33 -> 22473.941 | O33: 20497.77 | P33: 32105.63 | Q33: Si
A34: D-01-05-G07 | C34: TOYOTA | D34: 041523108000 | E34: FILTRO DE ACEITE | F34: IJ | G34: 2 | H34: 2 | I34: =+H34-G34 -> 0 | K34: SC | L34: SC | M34: 18994.262 | N34: =+M34*G34 -> 37988.524 | O34: 13633.09 | P34: 27134.66 | Q34: Si
A35: D-03-00-A01 | C35: TOYOTA | D35: 435120K32000 | E35: DISCO FRENO DEL. | F35: IJ | G35: 6 | H35: 6 | I35: =+H35-G35 -> 0 | J35: Mal Locado | K35: SC | L35: NC | M35: 177088.36 | N35: =+M35*G35 -> 1062530.2 | O35: 173927.09 | P35: 252983.37 | Q35: Si
A36: D-03-00-A02 | C36: TOYOTA | D36: 435120K08000 | E36: DISCO DE FRENO | F36: IJ | G36: 2 | H36: 2 | I36: =+H36-G36 -> 0 | J36: Mal Locado | K36: SC | L36: NC | M36: 158682.42 | N36: =+M36*G36 -> 317364.84 | O36: 155846.6 | P36: 226689.17 | Q36: Si
A37: D-03-00-B01 | C37: TOYOTA | D37: 044652646000 | E37: PASTILLAS DE FRENO DEL. | F37: IJ | G37: 2 | H37: 2 | I37: =+H37-G37 -> 0 | K37: SC | L37: SC | M37: 218024.02 | N37: =+M37*G37 -> 436048.05 | O37: 167133.91 | P37: 311462.89 | Q37: Si
A38: D-03-00-B02 | C38: TOYOTA | D38: 044662013000 | E38: JGO. PASTILLAS FRENO | F38: IJ | G38: 1 | H38: 1 | I38: =+H38-G38 -> 0 | K38: SC | L38: SC | M38: 10466.953 | N38: =+M38*G38 -> 10466.953 | O38: 326.78 | P38: 14952.79 | Q38: Si
A39: D-03-00-B03 | C39: TOYOTA | D39: 044664203000 | E39: JGO. PASTILLAS FRENO | F39: IJ | G39: 5 | H39: 5 | I39: =+H39-G39 -> 0 | K39: SC | L39: SC | M39: 103307.64 | N39: =+M39*G39 -> 516538.19 | O39: 3587.58 | P39: 147582.34 | Q39: Si
A40: D-03-00-B04 | C40: TOYOTA | D40: 044660501000 | E40: JGO. PASTILLAS FRENO | F40: IJ | G40: 1 | H40: 1 | I40: =+H40-G40 -> 0 | K40: SC | L40: SC | M40: 122621.67 | N40: =+M40*G40 -> 122621.67 | O40: 5327.79 | P40: 175173.82 | Q40: Si
A41: D-03-00-B06 | C41: TOYOTA | D41: 044666012000 | E41: JGO. PASTILLAS FRENO | F41: IJ | G41: 2 | H41: 2 | I41: =+H41-G41 -> 0 | K41: SC | L41: SC | M41: 147086.11 | N41: =+M41*G41 -> 294172.23 | O41: 5664.51 | P41: 210123.02 | Q41: Si
...

Sheet 7.Remito Pend de Fact
A1: AUTOLUX S.A.
A2: Subsistema Ventas
F4: Pendiente de Facturar
A6: ( 50105) | F6: Suc.: Casa Central - Jujuy Agrupado: Cliente
A7: Cliente: LEDESMA S.A.A.I. | F7: ( 50105) | M7: 0.5
A8: Fecha | C8: Comprobante | D8: Artículo | E8: Descripción | H8: Suc. | I8: Cantid. | J8: Pcio.Unit. | K8: Total | L8: Justif Control Ant | M8: Cumplimiento
A9: 45485 | C9: R-0005-00003816 | D9: 1 | E9: 90366T006100 | F9: IJ | G9: RODAMIENTO | H9: 2 | I9: 2 | J9: 137030.67 | K9: 274061.34 | L9: REMITO QUE SE HIZO A LEDESMA, NO LLAMO AL REMITO QUE ESTABA // ver mail | M9: SC
A10: 45485 | C10: R-0005-00003816 | D10: 1 | E10: 90916T200600 | F10: IJ | G10: CORREA | H10: 2 | I10: 4 | J10: 53655.18 | K10: 214620.72 | L10: REMITO QUE SE HIZO A LEDESMA, NO LLAMO AL REMITO QUE ESTABA /ver mail | M10: SC
A11: 45987 | C11: R-0005-00004364 | D11: 1 | E11: 443050K03000 | F11: IJ | G11: TAPA RESERVORIO | H11: 2 | I11: 1 | J11: 26908.78 | K11: 26908.78 | L11: Se olvidaron de facturar el remito - | M11: NC
A13: ( 55788)
F14: Artículos Componentes de Kit de Repuestos
G17: Total General
G18: Total Cliente | H18: =SUBTOTAL(9,I9:I13) -> 7 | I18: 515590.84
A20: Cliente: MINA PIRQUITAS S.A
A21: 46050 | C21: R-0005-00004421 | D21: 1 | E21: 903114704100 | F21: IJ | G21: RETEN SEMIEJ. IZQ. | H21: 2 | I21: 1 | J21: 53047.04 | K21: 53047.04 | L21: Se olvidaron de facturar el remito - | M21: NC
A22: 46050 | C22: R-0005-00004421 | D22: 1 | E22: 137500E01000 | F22: IJ | G22: BOTADOR | H22: 2 | I22: 16 | J22: 53914.46 | K22: 862631.36 | L22: Se olvidaron de facturar el remito -
A23: 46050 | C23: R-0005-00004421 | D23: 1 | E23: 270600L16000 | F23: IJ | G23: ALTERNADOR CON REGULADOR (denso) | H23: 2 | I23: 1 | J23: 1264462.8 | K23: 1264462.8 | L23: Se olvidaron de facturar el remito -
A24: 46050 | C24: R-0005-00004421 | D24: 1 | E24: 049420K16000 | F24: IJ | G24: JGO. REP. RESORTES ZAPATA FRENO | H24: 2 | I24: 1 | J24: 35990.33 | K24: 35990.33 | L24: Se olvidaron de facturar el remito -
A25: 46050 | C25: R-0005-00004421 | D25: 1 | E25: 443100K13000 | F25: IJ | G25: BOMBA DIRECCION HIDRAULIC | H25: 2 | I25: 2 | J25: 1680247.9 | K25: 3360495.9 | L25: Se olvidaron de facturar el remito -
A26: 46050 | C26: R-0005-00004421 | D26: 1 | E26: 894817101000 | F26: IJ | G26: SENSOR DIF. PRESION | H26: 2 | I26: 1 | J26: 430030.41 | K26: 430030.41 | L26: Se olvidaron de facturar el remito -
A27: 46050 | C27: R-0005-00004421 | D27: 1 | E27: 894257107000 | F27: IJ | G27: SENSOR TEMPERATURA GAS | H27: 2 | I27: 2 | J27: 723719.01 | K27: 1447438 | L27: Se olvidaron de facturar el remito -
A28: 46050 | C28: R-0005-00004421 | D28: 1 | E28: 281000L20100 | F28: IJ | G28: MOTOR DE ARRANQUE | H28: 2 | I28: 1 | J28: 1576859.5 | K28: 1576859.5 | L28: Se olvidaron de facturar el remito -
A29: 46050 | C29: R-0005-00004421 | D29: 1 | E29: 049490K07000 | F29: IJ | G29: JGO.REPAR.FRENO TRAS | H29: 2 | I29: 1 | J29: 12216.94 | K29: 12216.94 | L29: Se olvidaron de facturar el remito -
A30: 46050 | C30: R-0005-00004421 | D30: 1 | E30: 480680K12100 | F30: IJ | G30: PARRILLA SUSPENSION | H30: 2 | I30: 2 | J30: 389603.31 | K30: 779206.62 | L30: Se olvidaron de facturar el remito -
A31: 46050 | C31: R-0005-00004421 | D31: 1 | E31: 137160E01000 | F31: IJ | G31: TAPON VASTAGO VALV. | H31: 2 | I31: 17 | J31: 1971.07 | K31: 33508.19 | L31: Se olvidaron de facturar el remito -
F33: Artículos Componentes de Kit de Repuestos
G36: Total General
G37: Total Cliente | H37: =SUBTOTAL(9,I21:I32) -> 45 | I37: 9855887.1
G39: Total General | H39: =SUBTOTAL(9,I9:I38) -> 10371530 | I39: 10371478
J41: Fecha y Hora de Emisión: 03/02/2026 11:36 Página: 1/1

Sheet 8.Ventas Internas
A1: AUTOLUX S.A.
A2: Subsistema Ventas
E3: Ventas de Repuestos c/Internas
F5: Suc.: Casa Central - Jujuy Desde: 01/01/2026 Hasta: 31/01/2026 Formato: Resumido
A6: Fecha | B6: Cpbte. | E6: Nro. Cpbte. | F6: Interna | I6: Importe | J6: =+COUNTIF(J12:J83,"sc")/(COUNTIF(J12:J83,"sc")+COUNTIF(J12:J83,"nc")) -> 1
A7: 46030 | B7: Vta. Mostrador | C7: 2 | D7: 15011 | F7: Insumos Varios Taller | I7: 1013209.4 | J7: SC | K7: Firmado por Augusto fasciano
A8: 46024 | B8: Vta. Taller | C8: 2 | D8: 239624 | F8: Cortesias - TMS | I8: 27733.24
A9: 46024 | B9: Vta. Taller | C9: 2 | D9: 239628 | F9: Cortesías - Planes | I9: 67262.85
A10: 46024 | B10: Vta. Taller | C10: 2 | D10: 239629 | F10: Cortesias - TMS | I10: 57173.43
A11: 46024 | B11: Dev. Taller | C11: 2 | D11: 194954 | F11: Cortesías - Planes | I11: -67262.85
A12: 46027 | B12: Vta. Taller | C12: 2 | D12: 239638 | F12: Reparación Usadas | I12: 807220.01 | J12: SC
A13: 46027 | B13: Vta. Taller | C13: 2 | D13: 239670 | F13: Reparación Usadas | I13: 819328.3 | J13: SC
A14: 46027 | B14: Vta. Taller | C14: 2 | D14: 239679 | F14: Cortesías - Planes | I14: 52271.75
A15: 46027 | B15: Dev. Taller | C15: 2 | D15: 194957 | F15: Reparación Usadas | I15: -807220.01
A16: 46034 | B16: Vta. Mostrador | C16: 2 | D16: 15013 | F16: Reparación Usadas | I16: 451498.45 | J16: SC | K16: Firmado por Esteban Toril
A17: 46045 | B17: Vta. Mostrador | C17: 2 | D17: 15019 | F17: Preparación Pre-Entrega | I17: 230804.5 | J17: SC | K17: Firmado por Jorge Jijena
A18: 46028 | B18: Vta. Mostrador | C18: 2 | D18: 15007 | F18: Reparación Usadas | I18: 189038.88 | J18: SC | K18: Firmado por Martin Diaz
A19: 46038 | B19: Vta. Mostrador | C19: 2 | D19: 15017 | F19: Preparación Pre-Entrega | I19: 186193.82 | J19: SC | K19: Firmado por Jorge Jijena
A20: 46045 | B20: Vta. Mostrador | C20: 2 | D20: 15020 | F20: Reparación Usadas | I20: 158751.21 | J20: SC | K20: Firmado por Martin Diaz
A21: 46028 | B21: Vta. Mostrador | C21: 2 | D21: 15004 | F21: Reparación Usadas | I21: 151892.85 | J21: SC | K21: Firmado por Esteban Toril
A22: 46034 | B22: Vta. Mostrador | C22: 2 | D22: 15012 | F22: Cortesías - 0km | I22: 91874.82
A23: 46028 | B23: Vta. Taller | C23: 2 | D23: 239717 | F23: Cortesías - Planes | I23: 52271.75
A24: 46028 | B24: Vta. Taller | C24: 2 | D24: 239727 | F24: Cortesias - TMS | I24: 167560.42
A25: 46028 | B25: Vta. Taller | C25: 2 | D25: 239729 | F25: Cortesias - TMS | I25: 24538.51
A26: 46028 | B26: Vta. Taller | C26: 2 | D26: 239732 | F26: Cortesias - TMS | I26: 244038.15
A27: 46037 | B27: Vta. Mostrador | C27: 2 | D27: 15016 | F27: Cortesías - 0km | I27: 91874.82
A28: 46024 | B28: Vta. Mostrador | C28: 2 | D28: 15001 | F28: Cortesias - Repuestos | I28: 45030
A29: 46029 | B29: Vta. Taller | C29: 2 | D29: 239775 | F29: Cortesías - Planes | I29: 27733.24
A30: 46029 | B30: Vta. Taller | C30: 2 | D30: 239776 | F30: Cortesía Ventas - Taller | I30: 276223.02 | J30: SC
A31: 46029 | B31: Vta. Taller | C31: 2 | D31: 239791 | F31: Cortesías - Planes | I31: 474362.73
A32: 46029 | B32: Vta. Taller | C32: 2 | D32: 239801 | F32: Cortesías - Planes | I32: 474362.73
A33: 46029 | B33: Vta. Taller | C33: 2 | D33: 239811 | F33: Cortesías - Planes | I33: 203944.84
A34: 46029 | B34: Vta. Taller | C34: 2 | D34: 239815 | F34: Cortesías - Planes | I34: 265073.02
A35: 46029 | B35: Vta. Taller | C35: 2 | D35: 239817 | F35: Cortesías - 0km | I35: 652555.43
A36: 46029 | B36: Dev. Mostrador | C36: 2 | D36: 854 | F36: Cortesía Ventas - Taller | I36: -20208.18
A37: 46029 | B37: Dev. Taller | C37: 2 | D37: 194963 | F37: Cortesías - Planes | I37: -203944.84
A38: 46028 | B38: Vta. Mostrador | C38: 2 | D38: 15003 | F38: Reparación Usadas | I38: 28605.51
A39: 46030 | B39: Vta. Taller | C39: 2 | D39: 239833 | F39: Cortesías - Planes | I39: 45910.99
A40: 46030 | B40: Vta. Taller | C40: 2 | D40: 239841 | F40: Cortesías - 0km | I40: 295819.66
A41: 46030 | B41: Vta. Taller | C41: 2 | D41: 239871 | F41: Cortesías - Planes | I41: 47638.09
...

Sheet 9.Transf.Pend. Entrega
A1: AUTOLUX S.A.
A2: Subsistema Stock
F3: Transferencias de Stock Pendientes de Recepción
F5: Estado: Pendientes Suc.Origen: Casa Central - Jujuy Suc.Destino: Todas Kits de Repuestos: No Observaciones: No Valorizado: Costo de Compra Formato: Detallado
A6: Fecha | C6: Nro. Cpbte. | D6: Sucursal Origen | E6: Sucursal Destino | G6: Usuario | I6: Cantid. Total | K6: Cumplimiento | L6: Obs
A7: 46056 | C7: 00005217 | D7: Casa Central - Jujuy | E7: Suc. Tartagal | G7: Chauque, Hugo | I7: =SUBTOTAL(9,I9:I11) -> 0 | J7: 1079596.2 | K7: SC | L7: Transferencias pendientes de recepcionar con fecha igual a la ejecucion del control
C8: Linea | D8: Artículo | E8: Ind. | F8: Denominación | I8: Cantid. | K8: Valoriz.
B9: 1 | C9: 14881001 | D9: IJ | E9: 265/65/17 DUELER A/T REVO 2 | I9: 3 | J9: 657189.36
B10: 1 | C10: GRARRANCADOR | D10: IJ | E10: ARRANCADOR DE BATERIA GR | I10: 1 | J10: 97537.85
B11: 1 | C11: 18909001 | D11: IJ | E11: 225/45 R17 94W TURANZA ER300 | I11: 2 | J11: 324868.98
F12: Totales Generales | H12: =SUBTOTAL(9,I7:I11) -> 0 | I12: 1079596.2
J13: Fecha y Hora de Emisión: 03/02/2026 10:5 Página: 1/1
K14: 1

Sheet KPI'S
B2: INDICADORES
B4: CONTROL DE DEPÓSITO
B5: Categoría | C5: Características
B6: Periódo: Actual | C6: Corresponde al momento en el que realizamos el control en depósito
B7: Alcance: Muestreo | C7: Tanto el control de documentación como el inventario físico de mercaderías se basará en una muestra elegida, previo análisis del stock y corte de documentación.
B9: Referencias
B10: SC | C10: Si Cumple
B11: PC | C11: Parcialmente Cumple
B12: NC | C12: No Cumple
B14: PARÁMETROS A CONSIDERAR
B17: ENTRADA DE MERCADERÍAS
B19: Transferencias Pendientes de Recepción | C19: Evaluar la antigüedad de la transferencia pendiente, en función de la distancia existente entre sucursales.
B20: SC | C20: Transferencias que no superen el plazo previsto de antigüedad, definido por distancia entre sucursales.
B21: PC | C21: Transferencias que superan el plazo previsto de antigüedad, autorizadas o con una gestíon especial.
B22: NC | C22: Transferencias que superan el plazo previsto de antigüedad.
B24: Distancias | C24: Plazo- Hasta:
B25: Entre sucursales de una misma locaclidad | C25: 2 días
B26: Entre sucursales de Salta - Jujuy | C26: 2 días
B27: Viajes al interior | C27: 3 días
B29: Pendientes de Crédito | C29: Analizar que los repuestos pendientes de crédito cuenten con sus reclamos respectivos.
B30: SC | C30: Todos los pendientes de crédito cuentan con sus respectivos reclamos
B31: PC
B32: NC | C32: Al menos un repuesto pendiente de crédito no cuenta con reclamo.
B34: Remitos de proveedores | C34: Verificar los remitos recepcionados no superen el plazo de 48 hs, de forma tal que la mercaderia recibida se convierta en inventario registrado.
B35: SC | C35: Remitos recepcionados e ingresados en sistema en un plazo de 48 horas.
B36: PC | C36: Remitos pendientes de recepción que superan el plazo previsto de 48 horas, autorizados.
B37: NC | C37: Remitos pendientes de recepción que superan el plazo previsto de 48 horas.
B40: STOCK DE MERCADERÍAS
B42: Rdo. Inv. Rotativo | C42: Calificar la diferencia absoluta del resultado final del inventario rotativo, que refleja la correcta gestión en el manejo del stock.
B43: SC | C43: Diferencia absoluta < 1%
B44: PC | C44: Diferencia absoluta > 1% y < 2%
B45: NC | C45: Diferencia absoluta > 2%
B47: Locación | C47: Verificar que la locación prevista en sistema coincida con la ubicación física de los artículos.
B48: SC | C48: Desvíos en la señalización y localización de los artículos de hasta el 1% del total de la muestra- Ejemplo: 2 artículos mal locados sobre un total de 200
B49: PC | C49: Desvíos en la señalización y localización de los artículos de hasta el 3% del total de la muestra- Ejemplo: 6 artículos mal locados sobre un total de 200
B50: NC | C50: Desvíos en la señalización y localización de los artículos mayor al 3% del total de la muestra
B52: Estado de Art. | C52: Verificar que los artículos no se encuentren en calidad defectuosa que le impidan su comercialización.
B53: SC | C53: Desvíos en la calidad de los artículos de hasta el 0% del total de la muestra- Ejemplo: 0 artículos defecuosos sobre un total de 200.
B54: PC | C54: Desvíos en la calidad de los artículos de hasta el 1% del total de la muestra- Ejemplo: 2 artículos defecuosos sobre un total de 200.
B55: NC | C55: Desvíos en la calidad de los artículos mayor al 1% del total de la muestra
...

Sheet Salta-Jujuy
B2: Control Integral de Depósito
B3: Tablero de Resultados
B23: Tablero de Resultados - Control Integral de Depósito
B24: Sucursal: | C24: Casa Central Jujuy | F24: Fecha de realización: | G24: 46056
B25: Auditor: | C25: Gustavo Zambrano | F25: Codigo Auditoria: | G25: PROG - 858
B26: Etapas | C26: Parámetros | E26: Ponderación | F26: % Cumplimiento | G26: Resultado final
B27: Entradas | C27: 1. Transf. Pend. de Recepción | E27: 0.1 | F27: =+F48 -> 1 | G27: =+E27*F27 -> 0.1
C28: 2. Pendientes de Crédito | E28: 0.075 | F28: =+F69 -> 1 | G28: =+E28*F28 -> 0.075
C29: 3. Remito de Compras | E29: 0.025 | F29: =+F81 -> 1 | G29: =+E29*F29 -> 0.025
B30: Stock | C30: 4. Rdo. Inv. Rotativo | E30: 0.5 | F30: =+F94 -> 1 | G30: =+E30*F30 -> 0.5
C31: 5. Locación | E31: 0.1 | F31: =+'4.Inv Rota'!L5 -> 0.94117647 | G31: =+E31*F31 -> 0.094117647
C32: 6. Estado de Art. | E32: 0.025 | F32: =+'4.Inv Rota'!K5 -> 1 | G32: =+E32*F32 -> 0.025
B33: Salidas | C33: 7. Remitos Pend. de Facturación | E33: 0.025 | F33: =+F135 -> 0.5 | G33: =+E33*F33 -> 0.0125
C34: 8. Ventas Internas Directas | E34: 0.05 | F34: =+F148 -> 1 | G34: =+E34*F34 -> 0.05
C35: 9. Transf. Pend. De Entrega | E35: 0.1 | F35: =+F154 -> 1 | G35: =+E35*F35 -> 0.1
E36: =SUM(E27:E35) -> 1 | G36: =SUM(G27:G35) -> 0.98161765
B38: Detalle de Desvíos:
A39: Entradas
A40: 1. Transf. Pend. de Recepción
B41: Cantidad total de transferencias, según SIAC: | E41: 3
B42: Transferencias con observaciones: | E42: 0
B44: Fecha | C44: Nro. Cpbte. | D44: Sucursal Origen | E44: Valoriz. Total | F44: Cant. días demora
B46: Plazo promedio en días de recepción de Transferencias con Desvío | F46: =AVERAGE(F45:F45) -> #DIV/0!
B47: (*) Se puede agregar más detalle con referencia a la fila. | I47: ← Se puede agregar más comentarios aquí
B48: Grado de cumplimiento para Transf. Pend. De Recepción: | F48: =+'1,Tranf.Pend. Recep'!K15 -> 1
A50: 2. Pendientes de Crédito
B51: Cantidad total de Artículos Pendientes de Crédito, según SIAC: | E51: 5
B52: Pendientes de Crédito con observaciones: | E52: 5
B54: Únicamente a modo informativo, y sin impacto en el resultado del control, se detalla a continuación el siguiente crédito pendiente:
B56: Artículo | C56: Fecha | D56: Comprobante | E56: Cantidad | F56: Observacion
B57: 08021LL02000 | C57: =+VLOOKUP(B57,'2.Pend.Creditoo'!A$17:N$35,6,0) -> 45688 | D57: =+VLOOKUP(B57,'2.Pend.Creditoo'!A$17:N$35,9,0) -> A-0300-00148818 | E57: =+VLOOKUP(B57,'2.Pend.Creditoo'!A$17:N$35,14,0) -> 12 | F57: Se detecto que el comprobante observado fue registrado contablemente en el ejercicio 2025, pese a haber sido emitida por el proveedor en febrero de 2024. Los remitos asociados a dicha operación fueron correctamente cargados en el sistema durante el ejercicio 2024, sin generar diferencias de stock, pero no fueron oportunamente vinculados a la factura correspondiente. Como consecuencia, la factura quedó registrada en un ejercicio posterior sin cancelación contra remitos, manteniéndose en estado pendiente de crédito para evitar impacto en inventarios.
B58: 088238014000 | C58: =+VLOOKUP(B58,'2.Pend.Creditoo'!A$17:N$35,6,0) -> 45688 | D58: =+VLOOKUP(B58,'2.Pend.Creditoo'!A$17:N$35,9,0) -> A-0300-00148818 | E58: =+VLOOKUP(B58,'2.Pend.Creditoo'!A$17:N$35,14,0) -> 10
B59: 178010L04000 | C59: =+VLOOKUP(B59,'2.Pend.Creditoo'!A$17:N$35,6,0) -> 45688 | D59: =+VLOOKUP(B59,'2.Pend.Creditoo'!A$17:N$35,9,0) -> A-0300-00148818 | E59: =+VLOOKUP(B59,'2.Pend.Creditoo'!A$17:N$35,14,0) -> 10
B60: PH3B00KA1000 | C60: =+VLOOKUP(B60,'2.Pend.Creditoo'!A$17:N$35,6,0) -> 45688 | D60: =+VLOOKUP(B60,'2.Pend.Creditoo'!A$17:N$35,9,0) -> A-0300-00148818 | E60: =+VLOOKUP(B60,'2.Pend.Creditoo'!A$17:N$35,14,0) -> 2
B61: PH3B10KA1100 | C61: =+VLOOKUP(B61,'2.Pend.Creditoo'!A$17:N$35,6,0) -> 45688 | D61: =+VLOOKUP(B61,'2.Pend.Creditoo'!A$17:N$35,9,0) -> A-0300-00148818 | E61: =+VLOOKUP(B61,'2.Pend.Creditoo'!A$17:N$35,14,0) -> 1
B62: PH7000KM10DO | C62: =+VLOOKUP(B62,'2.Pend.Creditoo'!A$17:N$35,6,0) -> 45688 | D62: =+VLOOKUP(B62,'2.Pend.Creditoo'!A$17:N$35,9,0) -> A-0300-00148818 | E62: =+VLOOKUP(B62,'2.Pend.Creditoo'!A$17:N$35,14,0) -> 1
B64: Fecha | C64: Artículo | D64: N° de Remito | E64: Total | F64: Observaciones
B65: 45469 | C65: 561010K41000 | D65: R-0033-00852594 | E65: 152617.67 | F65: Rechazado por envío erroneo de doc.
B66: 45469 | C66: 644610D07000 | D66: R-0033-00852594 | E66: 42796.48 | F66: Rechazado por envío erroneo de doc.
B67: Importe Total de Artículos con Desvío Pend. De Crédito | E67: =SUM(E65:E66) -> 195414.15
...

Sheet Config S-J
A1: NO MODIFICAR, TIENE FORMULAS
A2: CONFIGURACIÓN PARA HOJA DE: "TESORERÍAS Y TARTAGAL"
A3: CONFIGURACIÓN DEL GRÁFICO:
A4: ** Calificación para los rangos del gráfico:
A5: 35 | B5: SAT | C5: Satisfactorio
A6: 30 | B6: ADE | C6: Adecuado
A7: 17 | B7: SUJ | C7: Sujeto a mejora
A8: 12 | B8: NAD | C8: No adecuado
A9: 6 | B9: INS | C9: Insatisfactorio
A10: =SUM(A5:A9) -> 100 | B10: TOTAL
A12: ** Valor para la aguja del velocimetro:
A13: Valor | C13: =+'Salta-Jujuy'!G36*100 -> 98.161765
A15: ** Parametros para el tamaño de la aguja:
A16: Antes | C16: =C13-C17/2 -> 97.161765
A17: Puntero | C17: 2
A18: Después | C18: =SUM(A5:A10)-C16-C17 -> 100.83824
A20: CONFIGURACIÓN DEL TEXTO DE LA CALIFICACIÓN:
A21: ** Parametros para la calificación textual:
A22: Min | B22: Abrev. | C22: Calificación | D22: Definición
A23: 0.94 | B23: SAT | C23: Satisfactorio | D23: No existen desvíos, o si existen estos son escasos y no significativos.
A24: 0.82 | B24: ADE | C24: Adecuado | D24: Los desvíos requieren de seguimiento por parte del sector para evitar su reincidencia.
A25: 0.65 | B25: SUJ | C25: Sujeto a mejora | D25: Suficiente cantidad de desvíos significativos que requieren de acciones correctivas.
A26: 0.35 | B26: NAD | C26: No adecuado | D26: Numerosos e importantes devíos que requieren de acción inmediata.
A27: 0 | B27: INS | C27: Insatisfactorio | D27: Numerosos e importantes devíos que requieren de medidas.
A29: Detalle de la calificación: | C29: =+C13/100 -> 0.98161765
A31: → | B31: =IF(C29<A26,C27,IF(C29<A25,C26,IF(C29<A24,C25,IF(C29<A23,C24,C23)))) -> Satisfactorio
A32: → | B32: =VLOOKUP(B31,C23:D27,2,FALSE) -> No existen desvíos, o si existen estos son escasos y no significativos.
A34: CONFIGURACIÓN PARA LAS TARJETAS QUE CONTIENEN TEXTO:
A35: ** Tarjeta 1: Lugar | D35: =+'Salta-Jujuy'!C24 -> Casa Central Jujuy
A36: → Lista desplegable para las sucursales: | D36: Casa Central Jujuy
D37: Sucursal Salta
A39: ** Tarjeta 2: Muestra de Art. | D39: =+'Salta-Jujuy'!D88 -> 213
A42: ** Tarjeta 3: Fecha de realización arqueo | D42: =+'Salta-Jujuy'!G24 -> 46056

Sheet Rotativo
A1: Autolux S.A. - Sucursal Salta
A2: Control Integral de Depósito | C2: 815610K31000 | D2: =+D59/D58 -> 1.0701884
A3: Fecha: | B3: 45604 | E3: Inventario Rotativo | I3: =1-(COUNTIFS($I$5:$I$90,"NC")/COUNTA($D$5:$D$90)) -> 0.98837209 | J3: =1-(COUNTIFS($J$5:$J$90,"NC")/COUNTA($D$5:$D$90)) -> 1 | L3: Pendientes | Q3: Recuento | V3: Ajuste | Y3: =SUM(Y5:Y90) -> -1240272.4 | Z3: =SUM(Z5:Z90) -> 1.8368988e+08
A4: Locación | B4: Artículo | C4: Descripción | D4: Cto.Rep. | E4: Stock | F4: Conteo | G4: Dif. | H4: x Dif.Final | I4: Locación | J4: Estado | K4: Justificaciones | L4: 7924 | M4: Dev. Transf. | N4: TOTAL remitos | O4: Dif. Parcial | P4: Acción | Q4: Stock | R4: Recuento | S4: Dif. | T4: Dif. Final | U4: Ajuste | V4: Faltante | W4: Sobrante | X4: Canje | Y4: Dif.Valorizada | Z4: Stock Valorizado | AA4: % | AB4: % Acumulado
A5: A-01-A01 | B5: 10594001 | C5: 205/55 R16 91V Turanza ER300 | D5: 138147.13 | E5: -3 | F5: 1 | G5: =+F5-E5 -> 4 | H5: =+D5*G5 -> 552588.51 | I5: SC | J5: SC | K5: INGRESO DE TRANSFERENCIA X4 n°7924 SE RECEPCIONA LA TRANSFERENCIA EL DIA DE LA FECHA. STOCK OK. | L5: 4 | N5: =+SUM(L5:M5) -> 4 | O5: =-E5-N5+F5 -> 0 | P5: Recontar | Q5: 21 | R5: 22 | S5: =+R5-Q5 -> 1 | T5: =IF(G5=0,0,IF(P5="Recontar",S5,IF(P5="Ajustar",O5,IF(P5="Canje",G5)))) -> 1 | U5: Sin Ajuste | V5: =IF(U5=$V$4,T5,"0") -> 0 | W5: =IF(U5=$W$4,T5,"0") -> 0 | X5: =IF(U5=$V$4,0,IF(U5=$W$4,0,IF(U5="-",0,IF(U5="Sin Ajuste",0,T5)))) -> 0 | Y5: =+V5*D5+W5*D5 -> 0 | Z5: =+E5*D5 -> -414441.38 | AA5: =+Z5/$Z$3 -> -0.0022562015 | AB5: =+AA5 -> -0.0022562015
A6: A-01-A03 | B6: 14199001 | C6: 265/60R18 110H - DUELER HT 684 II | D6: 217804.45 | E6: 15 | F6: 14 | G6: =+F6-E6 -> -1 | H6: =+D6*G6 -> -217804.45 | I6: SC | J6: SC | K6: ARTICULO CRUZADO CON 15175001 15175001 (FISICO 2//VIRTUAL 1) SOBRANTE X1 | L6: Una de las cubiertas no tiene el mismo cód es por ello que sólo se conto /14) | N6: =+SUM(L6:M6) -> 0 | O6: =-E6-N6+F6 -> -1 | P6: Recontar | Q6: 31 | R6: 30 | S6: =+R6-Q6 -> -1 | T6: =IF(G6=0,0,IF(P6="Recontar",S6,IF(P6="Ajustar",O6,IF(P6="Canje",G6)))) -> -1 | U6: Canje A | V6: =IF(U6=$V$4,T6,"0") -> 0 | W6: =IF(U6=$W$4,T6,"0") -> 0 | X6: =IF(U6=$V$4,0,IF(U6=$W$4,0,IF(U6="-",0,IF(U6="Sin Ajuste",0,T6)))) -> -1 | Y6: =+V6*D6+W6*D6 -> 0 | Z6: =+E6*D6 -> 3267066.7 | AA6: =+Z6/$Z$3 -> 0.017785774 | AB6: =+AB5+AA6 -> 0.015529573
A7: B-02-05-C01 | B7: 15175001 | C7: 265/60R18 110T DUELER HT 684 II | D7: 219662.03 | E7: 1 | F7: 2 | G7: =+F7-E7 -> 1 | H7: =+D7*G7 -> 219662.03 | I7: SC | J7: SC | K7: ARTICULO CRUZADO CON 15175001 15175001 (FISICO 2//VIRTUAL 1) SOBRANTE X1 | N7: =+SUM(L7:M7) -> 0 | O7: =-E7-N7+F7 -> 1 | P7: Recontar | Q7: 1 | R7: 2 | S7: =+R7-Q7 -> 1 | T7: =IF(G7=0,0,IF(P7="Recontar",S7,IF(P7="Ajustar",O7,IF(P7="Canje",G7)))) -> 1 | U7: Canje A | V7: =IF(U7=$V$4,T7,"0") -> 0 | W7: =IF(U7=$W$4,T7,"0") -> 0 | X7: =IF(U7=$V$4,0,IF(U7=$W$4,0,IF(U7="-",0,IF(U7="Sin Ajuste",0,T7)))) -> 1 | Y7: =+V7*D7+W7*D7 -> 0 | Z7: =+E7*D7 -> 219662.03 | AA7: =+Z7/$Z$3 -> 0.0011958309 | AB7: =+AB6+AA7 -> 0.016725404
A8: A-02-02-B02 | B8: PH4020KM1000 | C8: PROTECTOR PARAG.HILUX`19 - CAT 2 | D8: 94407.061 | E8: 4 | F8: 4 | G8: =+F8-E8 -> 0 | H8: =+D8*G8 -> 0 | I8: SC | J8: SC | K8: - | L8: - | N8: =+SUM(L8:M8) -> 0 | O8: =-E8-N8+F8 -> 0 | P8: - | S8: =+R8-Q8 -> 0 | T8: =IF(G8=0,0,IF(P8="Recontar",S8,IF(P8="Ajustar",O8,IF(P8="Canje",G8)))) -> 0 | U8: - | V8: =IF(U8=$V$4,T8,"0") -> 0 | W8: =IF(U8=$W$4,T8,"0") -> 0 | X8: =IF(U8=$V$4,0,IF(U8=$W$4,0,IF(U8="-",0,IF(U8="Sin Ajuste",0,T8)))) -> 0 | Y8: =+V8*D8+W8*D8 -> 0 | Z8: =+E8*D8 -> 377628.24 | AA8: =+Z8/$Z$3 -> 0.0020557923 | AB8: =+AB7+AA8 -> 0.018781196
A9: A-02-03-B02 | B9: PH4010KM1000 | C9: PROTECTOR FRONTAL HX 2016 | D9: 85459.983 | E9: 3 | F9: 3 | G9: =+F9-E9 -> 0 | H9: =+D9*G9 -> 0 | I9: SC | J9: SC | K9: - | L9: - | N9: =+SUM(L9:M9) -> 0 | O9: =-E9-N9+F9 -> 0 | P9: - | S9: =+R9-Q9 -> 0 | T9: =IF(G9=0,0,IF(P9="Recontar",S9,IF(P9="Ajustar",O9,IF(P9="Canje",G9)))) -> 0 | U9: - | V9: =IF(U9=$V$4,T9,"0") -> 0 | W9: =IF(U9=$W$4,T9,"0") -> 0 | X9: =IF(U9=$V$4,0,IF(U9=$W$4,0,IF(U9="-",0,IF(U9="Sin Ajuste",0,T9)))) -> 0 | Y9: =+V9*D9+W9*D9 -> 0 | Z9: =+E9*D9 -> 256379.95 | AA9: =+Z9/$Z$3 -> 0.0013957217 | AB9: =+AB8+AA9 -> 0.020176918
A10: ABI-02-A01 | B10: 0400720171C0 | C10: CENTRO VOLANTE (BLACK) | D10: 117012.5 | E10: 9 | F10: 14 | G10: =+F10-E10 -> 5 | H10: =+D10*G10 -> 585062.48 | I10: SC | J10: SC | K10: Variacion en la operativa de campañas STOCK OK | L10: - | N10: =+SUM(L10:M10) -> 0 | O10: =-E10-N10+F10 -> 5 | P10: Recontar | Q10: 19 | R10: 19 | S10: =+R10-Q10 -> 0 | T10: =IF(G10=0,0,IF(P10="Recontar",S10,IF(P10="Ajustar",O10,IF(P10="Canje",G10)))) -> 0 | U10: Sin Ajuste | V10: =IF(U10=$V$4,T10,"0") -> 0 | W10: =IF(U10=$W$4,T10,"0") -> 0 | X10: =IF(U10=$V$4,0,IF(U10=$W$4,0,IF(U10="-",0,IF(U10="Sin Ajuste",0,T10)))) -> 0 | Y10: =+V10*D10+W10*D10 -> 0 | Z10: =+E10*D10 -> 1053112.5 | AA10: =+Z10/$Z$3 -> 0.0057331001 | AB10: =+AB9+AA10 -> 0.025910018
A11: ABI-02-B01 | B11: 0400720171B0 | C11: CENTRO VOLANTE (DK.GRAY) | D11: 117012.5 | E11: 7 | F11: 18 | G11: =+F11-E11 -> 11 | H11: =+D11*G11 -> 1287137.5 | I11: SC | J11: SC | K11: Variacion en la operativa de campañas STOCK OK | L11: - | N11: =+SUM(L11:M11) -> 0 | O11: =-E11-N11+F11 -> 11 | P11: Recontar | Q11: 15 | R11: 15 | S11: =+R11-Q11 -> 0 | T11: =IF(G11=0,0,IF(P11="Recontar",S11,IF(P11="Ajustar",O11,IF(P11="Canje",G11)))) -> 0 | U11: Sin Ajuste | V11: =IF(U11=$V$4,T11,"0") -> 0 | W11: =IF(U11=$W$4,T11,"0") -> 0 | X11: =IF(U11=$V$4,0,IF(U11=$W$4,0,IF(U11="-",0,IF(U11="Sin Ajuste",0,T11)))) -> 0 | Y11: =+V11*D11+W11*D11 -> 0 | Z11: =+E11*D11 -> 819087.48 | AA11: =+Z11/$Z$3 -> 0.0044590779 | AB11: =+AB10+AA11 -> 0.030369096
A12: ABI-03-C01 | B12: 040040712200 | C12: KIT FFX CABLE ESPIRAL | D12: 148788.51 | E12: 4 | F12: 11 | G12: =+F12-E12 -> 7 | H12: =+D12*G12 -> 1041519.6 | I12: SC | J12: SC | K12: Variacion en la operativa de campañas STOCK OK | L12: - | N12: =+SUM(L12:M12) -> 0 | O12: =-E12-N12+F12 -> 7 | P12: Recontar | Q12: 18 | R12: 18 | S12: =+R12-Q12 -> 0 | T12: =IF(G12=0,0,IF(P12="Recontar",S12,IF(P12="Ajustar",O12,IF(P12="Canje",G12)))) -> 0 | U12: Sin Ajuste | V12: =IF(U12=$V$4,T12,"0") -> 0 | W12: =IF(U12=$W$4,T12,"0") -> 0 | X12: =IF(U12=$V$4,0,IF(U12=$W$4,0,IF(U12="-",0,IF(U12="Sin Ajuste",0,T12)))) -> 0 | Y12: =+V12*D12+W12*D12 -> 0 | Z12: =+E12*D12 -> 595154.06 | AA12: =+Z12/$Z$3 -> 0.0032399937 | AB12: =+AB11+AA12 -> 0.033609089
A13: ABI-03-D01 | B13: 040050591200 | C13: KIT PLACA SUCCION COMB. | D13: 59893.631 | E13: 11 | F13: 6 | G13: =+F13-E13 -> -5 | H13: =+D13*G13 -> -299468.15 | I13: SC | J13: SC | K13: Variacion en la operativa de campañas STOCK OK | L13: - | N13: =+SUM(L13:M13) -> 0 | O13: =-E13-N13+F13 -> -5 | P13: Recontar | Q13: 12 | R13: 12 | S13: =+R13-Q13 -> 0 | T13: =IF(G13=0,0,IF(P13="Recontar",S13,IF(P13="Ajustar",O13,IF(P13="Canje",G13)))) -> 0 | U13: Sin Ajuste | V13: =IF(U13=$V$4,T13,"0") -> 0 | W13: =IF(U13=$W$4,T13,"0") -> 0 | X13: =IF(U13=$V$4,0,IF(U13=$W$4,0,IF(U13="-",0,IF(U13="Sin Ajuste",0,T13)))) -> 0 | Y13: =+V13*D13+W13*D13 -> 0 | Z13: =+E13*D13 -> 658829.94 | AA13: =+Z13/$Z$3 -> 0.0035866426 | AB13: =+AB12+AA13 -> 0.037195732
A14: B-04-03-D06 | B14: PH9600KM10PT | C14: KIT PERNOS TH PU ARG HX 2016 - CAT 3 | D14: 51692.48 | E14: 7 | F14: 7 | G14: =+F14-E14 -> 0 | H14: =+D14*G14 -> 0 | I14: SC | J14: SC | K14: - | L14: - | N14: =+SUM(L14:M14) -> 0 | O14: =-E14-N14+F14 -> 0 | P14: - | S14: =+R14-Q14 -> 0 | T14: =IF(G14=0,0,IF(P14="Recontar",S14,IF(P14="Ajustar",O14,IF(P14="Canje",G14)))) -> 0 | U14: - | V14: =IF(U14=$V$4,T14,"0") -> 0 | W14: =IF(U14=$W$4,T14,"0") -> 0 | X14: =IF(U14=$V$4,0,IF(U14=$W$4,0,IF(U14="-",0,IF(U14="Sin Ajuste",0,T14)))) -> 0 | Y14: =+V14*D14+W14*D14 -> 0 | Z14: =+E14*D14 -> 361847.36 | AA14: =+Z14/$Z$3 -> 0.0019698819 | AB14: =+AB13+AA14 -> 0.039165614
A15: B-04-07-B07 | B15: 811500K73000 | C15: OPTICA IZQUIERDA | D15: 691006.13 | E15: 2 | F15: 2 | G15: =+F15-E15 -> 0 | H15: =+D15*G15 -> 0 | I15: SC | J15: SC | K15: - | L15: - | N15: =+SUM(L15:M15) -> 0 | O15: =-E15-N15+F15 -> 0 | P15: - | S15: =+R15-Q15 -> 0 | T15: 0 | U15: - | V15: =IF(U15=$V$4,T15,"0") -> 0 | W15: =IF(U15=$W$4,T15,"0") -> 0 | X15: =IF(U15=$V$4,0,IF(U15=$W$4,0,IF(U15="-",0,IF(U15="Sin Ajuste",0,T15)))) -> 0 | Y15: =+V15*D15+W15*D15 -> 0 | Z15: =+E15*D15 -> 1382012.3 | AA15: =+Z15/$Z$3 -> 0.0075236168 | AB15: =+AB14+AA15 -> 0.04668923
A16: B-06-03-A03 | B16: 426110K77100 | C16: LLANTA CHAPA 16" DX 2011-2015 | D16: 188580.68 | E16: 1 | F16: 1 | G16: =+F16-E16 -> 0 | H16: =+D16*G16 -> 0 | I16: SC | J16: SC | K16: - | L16: - | N16: =+SUM(L16:M16) -> 0 | O16: =-E16-N16+F16 -> 0 | P16: - | S16: =+R16-Q16 -> 0 | T16: =+O16 -> 0 | U16: - | V16: =IF(U16=$V$4,T16,"0") -> 0 | W16: =IF(U16=$W$4,T16,"0") -> 0 | X16: =IF(U16=$V$4,0,IF(U16=$W$4,0,IF(U16="-",0,IF(U16="Sin Ajuste",0,T16)))) -> 0 | Y16: =+V16*D16+W16*D16 -> 0 | Z16: =+E16*D16 -> 188580.68 | AA16: =+Z16/$Z$3 -> 0.0010266253 | AB16: =+AB15+AA16 -> 0.047715856
A17: B-06-11-A01 | B17: 426110KF7200 | C17: LLANTA 17 CHAPA 17X7.5 | D17: 151958.66 | E17: 18 | F17: 17 | G17: =+F17-E17 -> -1 | H17: =+D17*G17 -> -151958.66 | I17: SC | J17: SC | K17: CRUZADA CON 426110KR80 426110KR80 SE ENCUENTRA SOBRANTE X1 | L17: - | N17: =+SUM(L17:M17) -> 0 | O17: =-E17-N17+F17 -> -1 | P17: Recontar | Q17: 15 | R17: 14 | S17: =+R17-Q17 -> -1 | T17: =IF(G17=0,0,IF(P17="Recontar",S17,IF(P17="Ajustar",O17,IF(P17="Canje",G17)))) -> -1 | U17: Canje B | V17: =IF(U17=$V$4,T17,"0") -> 0 | W17: =IF(U17=$W$4,T17,"0") -> 0 | X17: =IF(U17=$V$4,0,IF(U17=$W$4,0,IF(U17="-",0,IF(U17="Sin Ajuste",0,T17)))) -> -1 | Y17: =+V17*D17+W17*D17 -> 0 | Z17: =+E17*D17 -> 2735255.9 | AA17: =+Z17/$Z$3 -> 0.014890618 | AB17: =+AB16+AA17 -> 0.062606474
A18: B-06-11-A02 | B18: 426110KR8000 | C18: LLANTA CHAPA 17X6 | D18: 142247.43 | E18: 0 | F18: 1 | G18: =+F18-E18 -> 1 | H18: =+D18*G18 -> 142247.43 | I18: SC | J18: SC | K18: CRUZADA CON 426110KR80 426110KR80 SE ENCUENTRA SOBRANTE X1 | L18: - | N18: =+SUM(L18:M18) -> 0 | O18: =-E18-N18+F18 -> 1 | P18: Recontar | Q18: 15 | R18: 16 | S18: =+R18-Q18 -> 1 | T18: =IF(G18=0,0,IF(P18="Recontar",S18,IF(P18="Ajustar",O18,IF(P18="Canje",G18)))) -> 1 | U18: Canje B | V18: =IF(U18=$V$4,T18,"0") -> 0 | W18: =IF(U18=$W$4,T18,"0") -> 0 | X18: =IF(U18=$V$4,0,IF(U18=$W$4,0,IF(U18="-",0,IF(U18="Sin Ajuste",0,T18)))) -> 1 | Y18: =+V18*D18+W18*D18 -> 0 | Z18: =+E18*D18 -> 0 | AA18: =+Z18/$Z$3 -> 0 | AB18: =+AB17+AA18 -> 0.062606474
A19: D-01-02-A01 | B19: 871390K08000 | C19: FILTRO A/A | D19: 14403.347 | E19: 302 | F19: 300 | G19: =+F19-E19 -> -2 | H19: =+D19*G19 -> -28806.694 | I19: SC | J19: SC | K19: Variacion en la operativa de taller de ese dia STOCK OK.(RECONTAR) | L19: - | N19: =+SUM(L19:M19) -> 0 | O19: =-E19-N19+F19 -> -2 | P19: Recontar | Q19: 336 | R19: 336 | S19: =+R19-Q19 -> 0 | T19: =IF(G19=0,0,IF(P19="Recontar",S19,IF(P19="Ajustar",O19,IF(P19="Canje",G19)))) -> 0 | U19: Sin Ajuste | V19: =IF(U19=$V$4,T19,"0") -> 0 | W19: =IF(U19=$W$4,T19,"0") -> 0 | X19: =IF(U19=$V$4,0,IF(U19=$W$4,0,IF(U19="-",0,IF(U19="Sin Ajuste",0,T19)))) -> 0 | Y19: =+V19*D19+W19*D19 -> 0 | Z19: =+E19*D19 -> 4349810.8 | AA19: =+Z19/$Z$3 -> 0.023680188 | AB19: =+AB18+AA19 -> 0.086286662
A20: D-01-02-B01 | B20: 871390K01000 | C20: FILTRO AIRE ACOND. | D20: 19677.231 | E20: 247 | F20: 246 | G20: =+F20-E20 -> -1 | H20: =+D20*G20 -> -19677.231 | I20: SC | J20: SC | K20: Variacion en la operativa de taller de ese dia STOCK OK.(RECONTAR) | L20: - | N20: =+SUM(L20:M20) -> 0 | O20: =-E20-N20+F20 -> -1 | P20: Recontar | Q20: 243 | R20: 243 | S20: =+R20-Q20 -> 0 | T20: =IF(G20=0,0,IF(P20="Recontar",S20,IF(P20="Ajustar",O20,IF(P20="Canje",G20)))) -> 0 | U20: Sin Ajuste | V20: =IF(U20=$V$4,T20,"0") -> 0 | W20: =IF(U20=$W$4,T20,"0") -> 0 | X20: =IF(U20=$V$4,0,IF(U20=$W$4,0,IF(U20="-",0,IF(U20="Sin Ajuste",0,T20)))) -> 0 | Y20: =+V20*D20+W20*D20 -> 0 | Z20: =+E20*D20 -> 4860276.1 | AA20: =+Z20/$Z$3 -> 0.026459139 | AB20: =+AB19+AA20 -> 0.1127458
A21: D-01-03-A01 | B21: 233900L07000 | C21: FILTRO COMBUSTIBLE | D21: 6541.969 | E21: -1 | F21: 0 | G21: =+F21-E21 -> 1 | H21: =+D21*G21 -> 6541.969 | I21: SC | J21: SC | K21: ARTICULO CRUZADO CON 233900L050 233900L050 SE ENCUENTRA FALTANTE X1 | L21: - | N21: =+SUM(L21:M21) -> 0 | O21: =-E21-N21+F21 -> 1 | P21: Recontar | Q21: -1 | R21: 0 | S21: =+R21-Q21 -> 1 | T21: =IF(G21=0,0,IF(P21="Recontar",S21,IF(P21="Ajustar",O21,IF(P21="Canje",G21)))) -> 1 | U21: Sobrante | V21: =IF(U21=$V$4,T21,"0") -> 0 | W21: =IF(U21=$W$4,T21,"0") -> 1 | X21: =IF(U21=$V$4,0,IF(U21=$W$4,0,IF(U21="-",0,IF(U21="Sin Ajuste",0,T21)))) -> 0 | Y21: =+V21*D21+W21*D21 -> 6541.969 | Z21: =+E21*D21 -> -6541.969 | AA21: =+Z21/$Z$3 -> -3.5614205e-05 | AB21: =+AB20+AA21 -> 0.11271019 | AC21: No se puede ajustar.Ajuste realizado el 28/11/2024 se encontraba inhabilitado.
A22: D-01-05-A01 | B22: 233900L05000 | C22: FILTRO DE COMBUSTIBLE | D22: 40100.144 | E22: 1 | F22: 0 | G22: =+F22-E22 -> -1 | H22: =+D22*G22 -> -40100.144 | I22: SC | J22: SC | K22: ARTICULO CRUZADO CON 233900L050 233900L050 SE ENCUENTRA FALTANTE X1 | L22: - | N22: =+SUM(L22:M22) -> 0 | O22: =-E22-N22+F22 -> -1 | P22: Recontar | Q22: 154 | R22: =152+1 -> 153 | S22: =+R22-Q22 -> -1 | T22: =IF(G22=0,0,IF(P22="Recontar",S22,IF(P22="Ajustar",O22,IF(P22="Canje",G22)))) -> -1 | U22: Faltante | V22: =IF(U22=$V$4,T22,"0") -> -1 | W22: =IF(U22=$W$4,T22,"0") -> 0 | X22: =IF(U22=$V$4,0,IF(U22=$W$4,0,IF(U22="-",0,IF(U22="Sin Ajuste",0,T22)))) -> 0 | Y22: =+V22*D22+W22*D22 -> -40100.144 | Z22: =+E22*D22 -> 40100.144 | AA22: =+Z22/$Z$3 -> 0.0002183035 | AB22: =+AB21+AA22 -> 0.11292849
A23: D-01-04-B01 | B23: 90915YZZD200 | C23: FILTRO ACEITE | D23: 8285.928 | E23: 424 | F23: =503-50-60 -> 393 | G23: =+F23-E23 -> -31 | H23: =+D23*G23 -> -256863.77 | I23: SC | J23: SC | K23: Variacion en la operativa de taller de ese dia (SE ENCUENTRA SOBRANTE X1) CRUZADO CON 0415237010 QUE SE ENCUENTRA FALTANTE X1 | L23: - | N23: =+SUM(L23:M23) -> 0 | O23: =-E23-N23+F23 -> -31 | P23: Recontar | Q23: 504 | R23: =176+39+260+29+1 -> 505 | S23: =+R23-Q23 -> 1 | T23: =IF(G23=0,0,IF(P23="Recontar",S23,IF(P23="Ajustar",O23,IF(P23="Canje",G23)))) -> 1 | U23: Sobrante | V23: =IF(U23=$V$4,T23,"0") -> 0 | W23: =IF(U23=$W$4,T23,"0") -> 1 | X23: =IF(U23=$V$4,0,IF(U23=$W$4,0,IF(U23="-",0,IF(U23="Sin Ajuste",0,T23)))) -> 0 | Y23: =+V23*D23+W23*D23 -> 8285.928 | Z23: =+E23*D23 -> 3513233.5 | AA23: =+Z23/$Z$3 -> 0.019125896 | AB23: =+AB22+AA23 -> 0.13205439
A24: D-01-04-C01 | B24: 178012105000 | C24: FILTRO DE AIRE | D24: 18412.912 | E24: 51 | F24: 51 | G24: =+F24-E24 -> 0 | H24: =+D24*G24 -> 0 | I24: SC | J24: SC | K24: - | L24: - | N24: =+SUM(L24:M24) -> 0 | O24: =-E24-N24+F24 -> 0 | P24: - | S24: =+R24-Q24 -> 0 | T24: =IF(G24=0,0,IF(P24="Recontar",S24,IF(P24="Ajustar",O24,IF(P24="Canje",G24)))) -> 0 | U24: - | V24: =IF(U24=$V$4,T24,"0") -> 0 | W24: =IF(U24=$W$4,T24,"0") -> 0 | X24: =IF(U24=$V$4,0,IF(U24=$W$4,0,IF(U24="-",0,IF(U24="Sin Ajuste",0,T24)))) -> 0 | Y24: =+V24*D24+W24*D24 -> 0 | Z24: =+E24*D24 -> 939058.51 | AA24: =+Z24/$Z$3 -> 0.0051121952 | AB24: =+AB23+AA24 -> 0.13716658
A25: D-01-05-C04 | B25: 041523701000 | C25: CONJ.FILTRO ACEITE | D25: 12765.606 | E25: 183 | F25: 178 | G25: =+F25-E25 -> -5 | H25: =+D25*G25 -> -63828.03 | I25: SC | J25: SC | K25: Variacion en la operativa de taller de ese dia (SE ENCUENTRA FALTANTE X1) CRUZADO CON 90915YZZD2 QUE SE ENCUENTRA SOBRANTE X1 | L25: - | N25: =+SUM(L25:M25) -> 0 | O25: =-E25-N25+F25 -> -5 | P25: Recontar | Q25: 208 | R25: =175+7+10+15 -> 207 | S25: =+R25-Q25 -> -1 | T25: =IF(G25=0,0,IF(P25="Recontar",S25,IF(P25="Ajustar",O25,IF(P25="Canje",G25)))) -> -1 | U25: Faltante | V25: =IF(U25=$V$4,T25,"0") -> -1 | W25: =IF(U25=$W$4,T25,"0") -> 0 | X25: =IF(U25=$V$4,0,IF(U25=$W$4,0,IF(U25="-",0,IF(U25="Sin Ajuste",0,T25)))) -> 0 | Y25: =+V25*D25+W25*D25 -> -12765.606 | Z25: =+E25*D25 -> 2336105.9 | AA25: =+Z25/$Z$3 -> 0.012717663 | AB25: =+AB24+AA25 -> 0.14988424
A26: D-01-06-C03 | B26: 233905107000 | C26: FILTRO COMBUSTIBLE | D26: 39055.632 | E26: 4 | F26: 4 | G26: =+F26-E26 -> 0 | H26: =+D26*G26 -> 0 | I26: SC | J26: SC | K26: - | L26: - | N26: =+SUM(L26:M26) -> 0 | O26: =-E26-N26+F26 -> 0 | P26: - | S26: =+R26-Q26 -> 0 | T26: =IF(G26=0,0,IF(P26="Recontar",S26,IF(P26="Ajustar",O26,IF(P26="Canje",G26)))) -> 0 | U26: - | V26: =IF(U26=$V$4,T26,"0") -> 0 | W26: =IF(U26=$W$4,T26,"0") -> 0 | X26: =IF(U26=$V$4,0,IF(U26=$W$4,0,IF(U26="-",0,IF(U26="Sin Ajuste",0,T26)))) -> 0 | Y26: =+V26*D26+W26*D26 -> 0 | Z26: =+E26*D26 -> 156222.53 | AA26: =+Z26/$Z$3 -> 0.00085046889 | AB26: =+AB25+AA26 -> 0.15073471
A27: D-01-07-C03 | B27: 178013112000 | C27: FILTRO DE AIRE RAV4 | D27: 36648.717 | E27: 11 | F27: 11 | G27: =+F27-E27 -> 0 | H27: =+D27*G27 -> 0 | I27: SC | J27: SC | K27: - | L27: - | N27: =+SUM(L27:M27) -> 0 | O27: =-E27-N27+F27 -> 0 | P27: - | S27: =+R27-Q27 -> 0 | T27: =IF(G27=0,0,IF(P27="Recontar",S27,IF(P27="Ajustar",O27,IF(P27="Canje",G27)))) -> 0 | U27: - | V27: =IF(U27=$V$4,T27,"0") -> 0 | W27: =IF(U27=$W$4,T27,"0") -> 0 | X27: =IF(U27=$V$4,0,IF(U27=$W$4,0,IF(U27="-",0,IF(U27="Sin Ajuste",0,T27)))) -> 0 | Y27: =+V27*D27+W27*D27 -> 0 | Z27: =+E27*D27 -> 403135.89 | AA27: =+Z27/$Z$3 -> 0.0021946549 | AB27: =+AB26+AA27 -> 0.15292937
